<?xml version="1.0"?>
<robot name="InvertPendulam">

  <mujoco>
    <!-- <compiler meshdir="../meshes/" balanceinertia="true" /> -->
    <default>
      <geom friction="1.0 0.005 0.0001" />
    </default>
  </mujoco>

  <!-- material color setting -->
  <material name="#ffffff">
    <color rgba="1.000 1.000 1.000 1.0" />
  </material>
  <material name="#fff700">
    <color rgba="1.000 0.969 0.000 1.0" />
  </material>
  <material name="#ff0004">
    <color rgba="1.000 0.000 0.016 1.0" />
  </material>
  <material name="#0700ff">
    <color rgba="0.031 0.000 1.000 1.0" />
  </material>

  <link name="base_link">
    <inertial>
      <origin xyz="0 0 0" rpy="0 0 0" />
      <mass value="0.0" />
      <inertia ixx="0.01" ixy="0.0" ixz="0.0" iyy="0.01" iyz="0.0" izz="0.01" />
    </inertial>
  </link>

  <joint name="base_link_to_InvertPendualm_mainBody_CoG_origin" type="fixed">
    <origin xyz="0 0 0" rpy="0.0 0.0 1.57" />
    <axis xyz="1 0 0" />
    <parent link="base_link" />
    <child link="InvertPendualm_mainBody_CoG_origin" />
  </joint>

  <link name="InvertPendualm_mainBody_CoG_origin">
    <inertial>
      <origin xyz="0 0 0" rpy="0 0 0" />
      <mass value="1.1515" />
      <inertia ixx="0.0071955" ixy="-1.645e-8" ixz="3e-8" iyy="0.0121364" iyz="-0.0000054"
        izz="0.00569466" />
    </inertial>
    <visual>
      <origin xyz="0 0 0" rpy="0 0 0" />
      <geometry>
        <mesh filename="../meshes/InvertPendualm_mainBody_CoG_origin_binary.stl" />
      </geometry>
      <material name="#fff700" />
    </visual>
    <collision>
      <origin xyz="0 0 0" rpy="0 0 0" />
      <geometry>
        <mesh filename="../meshes/InvertPendualm_mainBody_CoG_origin_binary.stl" />
      </geometry>
    </collision>
  </link>

  <joint name="InvertPendualm_mainBody_CoG_origin_to_InvertPendulam_wheel_left_center_origin"
    type="continuous">
    <origin xyz="0.0 0.0 -0.0605" rpy="0.0 0.0 0.0" />
    <axis xyz="1 0 0" />
    <parent link="InvertPendualm_mainBody_CoG_origin" />
    <child link="InvertPendulam_wheel_left_center_origin" />
    <limit effort="12.0" velocity="31.0" />
  </joint>

  <link name="InvertPendulam_wheel_left_center_origin">
    <inertial>
      <origin xyz="0 0 0" rpy="0 0 0" />
      <mass value="0.06360116" />
      <inertia ixx="0.00014101" ixy="0.0" ixz="0.0" iyy="0.00007681" iyz="0.0"
        izz="0.00007681" />
    </inertial>
    <visual>
      <origin xyz="0 0 0" rpy="0 0 0" />
      <geometry>
        <mesh filename="../meshes/InvertPendulam_wheel_left_center_origin_binary.stl" />
      </geometry>
      <material name="#ff0004" />
    </visual>
    <collision>
      <origin xyz="0 0 0" rpy="0 0 0" />
      <geometry>
        <mesh filename="../meshes/InvertPendulam_wheel_left_center_origin_binary.stl" />
      </geometry>
    </collision>
  </link>

  <joint name="InvertPendualm_mainBody_CoG_origin_to_InvertPendulam_wheel_right_center_origin"
    type="continuous">
    <origin xyz="0.0 0.0 -0.0605" rpy="0.0 0.0 0.0" />
    <axis xyz="1 0 0" />
    <parent link="InvertPendualm_mainBody_CoG_origin" />
    <child link="InvertPendulam_wheel_right_center_origin" />
    <limit effort="12.0" velocity="31.0" />
  </joint>

  <link name="InvertPendulam_wheel_right_center_origin">
    <inertial>
      <origin xyz="0 0 0" rpy="0 0 0" />
      <mass value="0.06360116" />
      <inertia ixx="0.00014101" ixy="0.0" ixz="0.0" iyy="0.00007681" iyz="0.0"
        izz="0.00007681" />
    </inertial>
    <visual>
      <origin xyz="0 0 0" rpy="0 0 0" />
      <geometry>
        <mesh filename="../meshes/InvertPendulam_wheel_right_center_origin_binary.stl" />
      </geometry>
      <material name="#0700ff" />
    </visual>
    <collision>
      <origin xyz="0 0 0" rpy="0 0 0" />
      <geometry>
        <mesh filename="../meshes/InvertPendulam_wheel_right_center_origin_binary.stl" />
      </geometry>
    </collision>
  </link>

  <transmission name="wheel_left_trans">
    <type>transmission_interface/SimpleTransmission</type>
    <joint name="InvertPendualm_mainBody_CoG_origin_to_InvertPendulam_wheel_left_center_origin">
      <hardwareInterface>hardware_interface/EffortJointInterface</hardwareInterface>
    </joint>
    <actuator name="wheel_left_motor">
      <mechanicalReduction>1</mechanicalReduction>
    </actuator>
  </transmission>

  <transmission name="wheel_right_trans">
    <type>transmission_interface/SimpleTransmission</type>
    <joint name="InvertPendualm_mainBody_CoG_origin_to_InvertPendulam_wheel_right_center_origin">
      <hardwareInterface>hardware_interface/EffortJointInterface</hardwareInterface>
    </joint>
    <actuator name="wheel_right_motor">
      <mechanicalReduction>1</mechanicalReduction>
    </actuator>
  </transmission>


</robot>